<?xml version="1.0"?>

<robot xmlns:xacro="http://www.ros.org/wiki/xacro" name="diffbot">


    <!-- COLOR DEFINITIONS -->
    <material name="white">
        <color rgba="1 1 1 1" />
    </material>

    <material name="orange">
        <color rgba="1 0.3 0.1 1"/>
    </material>

    <material name="blue">
        <color rgba="0 0 1 1"/>
    </material>

    <material name="black">
        <color rgba="0 0 0 1"/>
    </material>

    <material name="brown">
        <color rgba="0.7 0.55 0.3 1"/>
    </material>

    <!-- ________________________ ARGUMENT DEFINITIONS ________________________ -->

    <!-- ROS2 VERSION -->
    <xacro:arg name="is_ignition" default="true"/>

    <!-- START SIMULATION OR REAL ROBOT -->
    <xacro:arg name="is_sim" default="true"/>

    <!-- ________________________ XACRO FILE DEPENDENCIES ________________________ -->

    <!-- INCLUDE INERTIAL MACROS -->
    <xacro:include filename="$(find diffbot_description)/urdf/inertial_macros.xacro"/>

    <!-- GAZEBO -->
    <xacro:include filename="$(find diffbot_description)/urdf/diffbot_gazebo.xacro"/>

    <!-- ROS2 CONTROL -->
    <xacro:include filename="$(find diffbot_description)/urdf/diffbot_ros2_control.xacro"/> 


    <!-- ________________________ DIFFBOT URDF MODEL ________________________ -->

    <!-- BASE LINK -->
    <link name="base_link"/>
    
    <!-- CHASSIS -->
    <joint name="chassis_joint" type="fixed">
        <parent link="base_link"/>
        <child link="chassis"/>
        <origin xyz="0 0 0.06"/>
    </joint>

    <link name="chassis">
        <visual>
            <origin xyz="0 0 0"/>
            <geometry>
                <box size="0.3 0.22 0.08"/>
            </geometry>
            <material name="brown"/>
        </visual>
        <collision>
            <origin xyz="0 0 0"/>
            <geometry>
                <box size="0.3 0.22 0.08"/>
            </geometry>
        </collision>
        <xacro:inertial_box mass="0.5" x="0.3" y="0.22" z="0.08">
            <origin xyz="0 0 0" rpy="0 0 0"/>
        </xacro:inertial_box>
    </link>


    <!-- LEFT WHEEL -->
    <joint name="wheel_left_joint" type="continuous">
        <parent link="base_link"/> 
        <child link="wheel_left"/>
        <origin xyz="-0.075 0.1225 0" rpy="-${pi/2} 0 0" />
        <axis xyz="0 0 1"/>
    </joint>

    <link name="wheel_left">
        <visual>
            <geometry>
                <cylinder radius="0.033" length="0.025"/>
            </geometry>
            <material name="blue"/>
        </visual>
        <collision>
            <geometry>
                <cylinder radius="0.033" length="0.025"/>
            </geometry>
        </collision>
        <xacro:inertial_cylinder mass="0.1" length="0.025" radius="0.033">
            <origin xyz="0 0 0" rpy="0 0 0"/>
        </xacro:inertial_cylinder>
    </link>

    <!-- RIGHT WHEEL -->

    <joint name="wheel_right_joint" type="continuous">
        <parent link="base_link"/>
        <child link="wheel_right"/>
        <origin xyz="-0.075 -0.1225 0" rpy="${pi/2} 0 0" />
        <axis xyz="0 0 -1"/>
    </joint>

    <link name="wheel_right">
        <visual>
            <geometry>
                <cylinder radius="0.033" length="0.025"/>
            </geometry>
            <material name="blue"/>
        </visual>
        <collision>
            <geometry>
                <cylinder radius="0.033" length="0.025"/>
            </geometry>
        </collision>
        <xacro:inertial_cylinder mass="0.1" length="0.025" radius="0.033">
            <origin xyz="0 0 0" rpy="0 0 0"/>
        </xacro:inertial_cylinder>
    </link>

    <!-- CASTER WHEEL -->

    <joint name="caster_wheel_joint" type="fixed">
        <parent link="base_link"/>
        <child link="caster_wheel"/>
        <origin xyz="0.075 0 0"/>
    </joint>


    <link name="caster_wheel">
        <visual>
            <geometry>
                <sphere radius="0.033"/>
            </geometry>
            <material name="black"/>
        </visual>
        <collision>
            <geometry>
                <sphere radius="0.033"/>
            </geometry>
        </collision>
        <xacro:inertial_sphere mass="0.1" radius="0.033">
            <origin xyz="0 0 0" rpy="0 0 0"/>
        </xacro:inertial_sphere>
    </link>

    <!-- IMU -->
    <link name="imu_link">
        <xacro:inertial_box mass="0.006" x="0.035" y="0.035" z="0.015">
            <origin xyz="0 0 0.003" rpy="0 0 0"/>
        </xacro:inertial_box>
        <visual>
            <origin xyz="0.0175 0.0175 0" rpy="${pi/2} 0 ${pi}"/>
            <geometry>
                <mesh filename="package://diffbot_description/meshes/WT901C.STL"/>
            </geometry>
            <material name="black"/>
        </visual>
        <collision>
            <origin xyz="0.0175 0.0175 0" rpy="${pi/2} 0 ${pi}"/>
            <geometry>
                <mesh filename="package://diffbot_description/meshes/WT901C.STL"/>
            </geometry>
        </collision>
    </link>

    <joint name="imu_joint" type="fixed">
        <origin xyz="${0.3/2 - 0.005 - 0.0175} ${0.22/2 - 0.025 - 0.0175} ${0.06+0.08/2}" rpy="0 0 0" />
        <parent link="base_link"/>
        <child link="imu_link"/>
        <axis xyz="0 0 0"/>
    </joint>

    <!-- LIDAR -->
    <link name="laser_link">
        <inertial> 
            <origin xyz="-0.011945780406062 -0.000381929217680526 -0.0170649378129477" rpy="0 0 0" />
            <mass value="0.073084435549317" />      
            <inertia ixx="1.96074931730795E-05" ixy="-3.62091076640009E-07" ixz="4.28230084046735E-07" iyy="2.40983835136327E-05" iyz="1.50180909250652E-08" izz="4.14184164228595E-05" />
        </inertial>
        <visual>
            <origin xyz="0 0 0" rpy="0 0 0"/>
            <geometry>
                <mesh filename="package://diffbot_description/meshes/laser_link.STL"/>
            </geometry>
            <material name="black"/>
        </visual>
        <collision>
            <origin xyz="0 0 0" rpy="0 0 0"/>
            <geometry>
                <mesh filename="package://diffbot_description/meshes/laser_link.STL"/>
            </geometry>
        </collision>
    </link>

    <joint name="laser_joint" type="fixed">
        <origin xyz="0 0 ${0.08 + 0.06}" rpy="0 0 3.14" />
        <parent link="base_link"/>
        <child link="laser_link"/>
        <axis xyz="0 0 0"/>
    </joint>

</robot>
